Workbook
Name Slicer_Category: #N/A
Name Slicer_Region: #N/A
Name Slicer_Segment: #N/A
Name Slicer_Ship_Mode: #N/A
Name Timeline_Order_Date: #N/A

Sheet Charts
AA1: Row Labels | AB1: Total Sales
AA2: California | AB2: =IFERROR(GETPIVOTDATA("[Measures].[Total Sales]",Analysis!$I$43,"[Location Dimension].[State]","[Location Dimension].[State].&["&AA2&"]"),0) -> 457687.63
AA3: New York | AB3: =IFERROR(GETPIVOTDATA("[Measures].[Total Sales]",Analysis!$I$43,"[Location Dimension].[State]","[Location Dimension].[State].&["&AA3&"]"),0) -> 310876.27
AA4: Texas | AB4: =IFERROR(GETPIVOTDATA("[Measures].[Total Sales]",Analysis!$I$43,"[Location Dimension].[State]","[Location Dimension].[State].&["&AA4&"]"),0) -> 170188.05
AA5: Washington | AB5: =IFERROR(GETPIVOTDATA("[Measures].[Total Sales]",Analysis!$I$43,"[Location Dimension].[State]","[Location Dimension].[State].&["&AA5&"]"),0) -> 138641.27
AA6: Pennsylvania | AB6: =IFERROR(GETPIVOTDATA("[Measures].[Total Sales]",Analysis!$I$43,"[Location Dimension].[State]","[Location Dimension].[State].&["&AA6&"]"),0) -> 116511.91
AA7: Florida | AB7: =IFERROR(GETPIVOTDATA("[Measures].[Total Sales]",Analysis!$I$43,"[Location Dimension].[State]","[Location Dimension].[State].&["&AA7&"]"),0) -> 89473.708
AA8: Illinois | AB8: =IFERROR(GETPIVOTDATA("[Measures].[Total Sales]",Analysis!$I$43,"[Location Dimension].[State]","[Location Dimension].[State].&["&AA8&"]"),0) -> 80166.101
AA9: Ohio | AB9: =IFERROR(GETPIVOTDATA("[Measures].[Total Sales]",Analysis!$I$43,"[Location Dimension].[State]","[Location Dimension].[State].&["&AA9&"]"),0) -> 78258.136
AA10: Michigan | AB10: =IFERROR(GETPIVOTDATA("[Measures].[Total Sales]",Analysis!$I$43,"[Location Dimension].[State]","[Location Dimension].[State].&["&AA10&"]"),0) -> 76269.614
AA11: Virginia | AB11: =IFERROR(GETPIVOTDATA("[Measures].[Total Sales]",Analysis!$I$43,"[Location Dimension].[State]","[Location Dimension].[State].&["&AA11&"]"),0) -> 70636.72
AA12: North Carolina | AB12: =IFERROR(GETPIVOTDATA("[Measures].[Total Sales]",Analysis!$I$43,"[Location Dimension].[State]","[Location Dimension].[State].&["&AA12&"]"),0) -> 55603.164
AA13: Indiana | AB13: =IFERROR(GETPIVOTDATA("[Measures].[Total Sales]",Analysis!$I$43,"[Location Dimension].[State]","[Location Dimension].[State].&["&AA13&"]"),0) -> 53555.36
... AA50: North Dakota | AB50: =IFERROR(GETPIVOTDATA("[Measures].[Total Sales]",Analysis!$I$43,"[Location Dimension].[State]","[Location Dimension].[State].&["&AA50&"]"),0) -> 919.91

Sheet Analysis
A1: Retail Sales Analysis
A6: Total Sales | C6: Total Profit | E6: How have Sales and Profit changed over time? | I6: Which regions generate the highest sales and profit?
A7: 2297200.9 | C7: 286397.02 | E7: Row Labels | F7: Total Sales | G7: Total Profit | I7: Row Labels | J7: Total Sales
E8: 2014 | F8: 484247.5 | G8: 49543.974 | I8: Central | J8: 501239.89
A9: Profit Margin | C9: Total Customers | E9: 2015 | F9: 470532.51 | G9: 61618.604 | I9: East | J9: 678781.24
A10: 0.12467217 | C10: 793 | E10: 2016 | F10: 609205.6 | G10: 81795.174 | I10: South | J10: 391721.91
E11: 2017 | F11: 733215.26 | G11: 93439.27 | I11: West | J11: 725457.82
A12: Total Quantity | C12: Total Orders | E12: Grand Total | F12: 2297200.9 | G12: 286397.02 | I12: Grand Total | J12: 2297200.9
A13: 37873 | C13: 5009
A15: Category | B15: All | E15: Who are the top 10 customers by sales? | I15: Which customer segments contribute the most to sales and profit?
A16: How do discounts affect profitability? | E16: Row Labels | F16: Total Sales | G16: Total Profit | I16: Row Labels | J16: Total Sales
A17: Row Labels | B17: Total Profit | E17: Sean Miller | F17: 25043.05 | G17: -1980.7393 | I17: Consumer | J17: 1161401.3
A18: 0 | B18: 320987.6 | E18: Tamara Chand | F18: 19052.218 | G18: 8981.3239 | I18: Corporate | J18: 706146.37
A19: 0.1 | B19: 9029.177 | E19: Raymond Buch | F19: 15117.339 | G19: 6976.0959 | I19: Home Office | J19: 429653.15
A20: 0.15 | B20: 1418.9915 | E20: Tom Ashbrook | F20: 14595.62 | G20: 4703.7883 | I20: Grand Total | J20: 2297200.9
A21: 0.2 | B21: 90337.306 | E21: Adrian Barton | F21: 14473.571 | G21: 5444.8055
A22: 0.3 | B22: -10369.277 | E22: Ken Lonsdale | F22: 14175.229 | G22: 806.855
A23: 0.32 | B23: -2391.1377 | E23: Sanjit Chand | F23: 14142.334 | G23: 5757.4119
A24: 0.4 | B24: -23057.05 | E24: Hunter Lopez | F24: 12873.298 | G24: 5622.4292 | I24: How do shipping modes compare in sales?
A25: 0.45 | B25: -2493.1111 | E25: Sanjit Engle | F25: 12209.438 | G25: 2650.6769 | I25: Row Labels | J25: Total Sales
A26: 0.5 | B26: -20506.428 | E26: Christopher Conant | F26: 12129.072 | G26: 2177.0493 | I26: First Class | J26: 351428.42
A27: 0.6 | B27: -5944.6552 | E27: Grand Total | F27: 153811.17 | G27: 41139.697 | I27: Same Day | J27: 128363.12
A28: 0.7 | B28: -40075.357 | I28: Second Class | J28: 459193.57
A29: 0.8 | B29: -30539.039 | I29: Standard Class | J29: 1358215.7
A30: Grand Total | B30: 286397.02 | I30: Grand Total | J30: 2297200.9
A33: Which sub-categories generate the highest and lowest profit? | E33: Which months generate the highest sales and profit? | I33: Year | J33: All
A34: Row Labels | B34: Total Profit | E34: Row Labels | F34: Total Sales | G34: Total Profit | I34: How do sales vary by category and sub-category?
A35: Copiers | B35: 55617.825 | E35: 2014 | I35: Row Labels | J35: Total Sales
A36: Phones | B36: 44515.731 | E36: Jan | F36: 14236.895 | G36: 2450.1907 | I36: Furniture | J36: 741999.8
A37: Accessories | B37: 41936.636 | E37: Feb | F37: 4519.892 | G37: 862.3084 | I37: Office Supplies | J37: 719047.03
A38: Paper | B38: 34053.569 | E38: Mar | F38: 55691.009 | G38: 498.7299 | I38: Technology | J38: 836154.03
A39: Binders | B39: 30221.763 | E39: Apr | F39: 28295.345 | G39: 3488.8352 | I39: Grand Total | J39: 2297200.9
A40: Chairs | B40: 26590.166 | E40: May | F40: 23648.287 | G40: 2738.7096
A41: Storage | B41: 21278.826 | E41: Jun | F41: 34595.128 | G41: 4976.5244
A42: Appliances | B42: 18138.005 | E42: Jul | F42: 33946.393 | G42: -841.4826 | I42: Which states generate the highest and lowest profit?
A43: Furnishings | B43: 13059.144 | E43: Aug | F43: 27909.468 | G43: 5318.105 | I43: Row Labels | J43: Total Sales
A44: Envelopes | B44: 6964.1767 | E44: Sep | F44: 81777.351 | G44: 8328.0994 | I44: California | J44: 457687.63
A45: Art | B45: 6527.787 | E45: Oct | F45: 31453.393 | G45: 3448.2573 | I45: New York | J45: 310876.27
A46: Labels | B46: 5546.254 | E46: Nov | F46: 78628.717 | G46: 9292.1269 | I46: Texas | J46: 170188.05
A47: Machines | B47: 3384.7569 | E47: Dec | F47: 69545.621 | G47: 8983.5699 | I47: Washington | J47: 138641.27
...

Sheet Overview Dashboard

Sheet Summary Dashboard
